// Which of the catch blocks will be involved as a result of this code execution?
static void Recursive()
{
    Recursive();
}
// Это метод Recursive(), который вызывает сам себя рекурсивно. Этот код создает бесконечную рекурсию, так как метод не имеет условия выхода из рекурсии.
try
{
    Recursive();
    //метод вызывает сам себя рекурсивно бесконечное количество раз, возникает исключение StackOverflowException.
}
catch (InsufficientMemoryException)
//исключение указывает на то, что доступной памяти оказалось недостаточно. Это исключение возникает только при явном использовании объекта MemoryFailPoint. Является производным типом от OutOfMemoryException.
{
    // block 1
    throw;
    // Конструкции throw в середине catch приводят к тому, что ошибка «передается на более высокий уровень», и даже если после текущего блока catch есть другой блок, способный перехватить эту ошибку по своему типу, он не будет выполнен. 
    //в данном случае этот блок не будет выполнен, так как возникшее исключение является StackOverflowException. Затем исключение снова выбрасывается (throw;), чтобы передать его на уровень выше.
}
catch (OutOfMemoryException)
//сообщает, что недостаточно памяти для продолжения выполнения программы. Исключение возникает либо при превышении максимального значения длины для StringBuilder, либо когда CLR не может выделить достаточно непрерывной памяти для выполнения операции (создание объекта, вызов метода и т. д.). Эта ошибка связана с кучей .
{
    // block 2
    throw;
    //перехватывает исключение OutOfMemoryException, но в данном случае этот блок также не будет выполнен по той же причине, что и предыдущий блок. Исключение снова выбрасывается (throw;).
}
catch (StackOverflowException)
//возникает, когда стек времени выполнения переполняется, потому что он содержит слишком много вызовов вложенных методов. Если эта ошибка не вызывается явно (посредством throw), ее нельзя перехватить с помощью try…catch. 
{
    // block 3
    throw;
    //перехватывает исключение StackOverflowException. Так как это исключение было сгенерировано внутри метода Recursive(), этот блок будет выполнен. В данном случае блок просто выбрасывает исключение снова (throw;), чтобы передать его на уровень выше.
}
catch (Exception)
//базовый тип для всех исключений. Используется для объявления перехвата любой ошибки. Теперь рассмотрим, что происходит в блоке try: вызывается метод Recursive(). Этот метод не использует MemoryFailPoint и не создает и не изменяет объекты, поэтому блоки 1 и 2 не будут задействованы. Вместо этого метод создает неконтролируемую рекурсию, которая переполняет стек и вызывает исключение StackOverflowException, сгенерированное системой. Поэтому блоки 3 и 4 также не будут задействованы. 
{
    // block 4
    throw;
    //перехватывает общее исключение Exception. Он будет выполнен только в том случае, если ни один из предыдущих блоков catch не перехватит исключение. В данном случае этот блок не будет выполнен, так как исключение уже было перехвачено блоком catch (StackOverflowException). Исключение снова выбрасывается (throw;).
}

Правильный ответ: д) ни один блок не будет задействован.


